<?xml version="1.0"?>
<robot xmlns:xacro="http://www.ros.org/wiki/xacro" >

    <joint name="camera_joint" type="revolute">
        <parent link="chassis"/>
        <child link="camera_link"/>
        <origin xyz="0.02 0.01 0.05" rpy="0 0 0"/>

        <axis xyz="0 0 1"/>
        <limit effort="2.0" lower="${-pi/2}" upper="${pi/2}" velocity="0.5"/>
       <dynamics damping="0.05" friction="0.05"/>
    </joint>

    <link name="camera_link">
        <visual>
            <origin xyz="0.02 0.01 0.0 " rpy="0 0 ${-pi/2}"/>
            <geometry>
                <mesh filename="package://pibotj_r2c/meshes/camara.stl" scale="0.001 0.001 0.001"/>
            </geometry>
            <material name="Blue"> <!-- Color en Rviz2-->
                <color rgba="${0/255} ${0/255} ${255/255} 1.0"/>
            </material>
        </visual>

        <!-- NECESARIO AÑADIRLO PARA QUE GAZEBO NO NOS IGNORE-->
        <collision> 
            <origin xyz="0.0 0.0 0.0 " rpy="0 0 ${-pi/2}"/>
            <geometry>
                <mesh filename="package://pibotj_r2c/meshes/camara.stl" scale="0.001 0.001 0.001"/>
            </geometry>
        </collision>
        <inertial>
            <origin xyz="0.0 0.0 0.0" rpy="0 0 ${-pi/2}"/>
            <mass value="0.03"/> <!--30g-->
            <inertia ixx="0.01" ixy="0.0" ixz="0.0" iyy="0.005" iyz="0.0" izz="0.005"/>
        </inertial>
        
    </link>

    <gazebo reference="camera_link">
        <material>Gazebo/Blue</material>
    </gazebo>


    <joint name="camera_optical_joint" type="fixed">
        <parent link="camera_link"/>
        <child link="camera_link_optical"/>
        <origin xyz="0.04 -0.006 0.018" rpy="0 0.8726 0"/>
    </joint>


    <!-- Cubo añadido donde va a ir la cámara-->
    <link name="camera_link_optical">
        <visual>
            <origin xyz="0 0 0" rpy="0 0 0"/>
            <geometry>
                <box size="0.01 0.01 0.01"/>
            </geometry>
        </visual>
    </link>

    <gazebo reference="camera_link_optical">
        <material>Gazebo/Blue</material>

        <sensor name="camera" type="camera">
            <pose> 0 0 0 0 0 0 </pose>
            <visualize>true</visualize>
            <update_rate>10</update_rate>
            <camera>
                <horizontal_fov>1.089</horizontal_fov>
                <image>
                    <format>R8G8B8</format>
                    <width>640</width>
                    <height>480</height>
                </image>
                <clip>
                    <near>0.05</near>
                    <far>8.0</far>
                </clip>
            </camera>
            <plugin name="camera_controller" filename="libgazebo_ros_camera.so">
                <frame_name>camera_link_optical</frame_name>
            </plugin>
        </sensor>
    </gazebo>

</robot>